<?xml version="1.0" ?>
<!-- =================================================================================== -->
<!-- |    This document was autogenerated by xacro from src/mmk2_description/urdf/mmk2.xacro | -->
<!-- |    EDITING THIS FILE BY HAND IS NOT RECOMMENDED                                 | -->
<!-- =================================================================================== -->
<robot name="mmk2" xmlns:controller="http://playerstage.sourceforge.net/gazebo/xmlschema/#controller" xmlns:interface="http://playerstage.sourceforge.net/gazebo/xmlschema/#interface" xmlns:sensor="http://playerstage.sourceforge.net/gazebo/xmlschema/#sensor">
  <link name="base_link">
    <inertial>
      <origin rpy="0 0 0" xyz="-0.0400313721989715 -0.0226608008968248 0.756257223317173"/>
      <mass value="33.0267456398628"/>
      <inertia ixx="3.44838378637062" ixy="-0.00207943141138886" ixz="-0.0103091786755565" iyy="3.49493780774117" iyz="-0.00146679448998739" izz="0.21980548376876"/>
    </inertial>
    <visual>
      <origin rpy="0 0 0" xyz="0 0 0"/>
      <geometry>
        <mesh filename="package://mmk2_urdf/meshes/slamtec_athena/visual/base_link.STL"/>
      </geometry>
      <material name="">
        <color rgba="0.752941176470588 0.752941176470588 0.752941176470588 1"/>
      </material>
    </visual>
    <collision>
      <origin rpy="0 0 0" xyz="0 0 0"/>
      <geometry>
        <mesh filename="package://mmk2_urdf/meshes/slamtec_athena/collision/base_link.STL"/>
      </geometry>
    </collision>
  </link>
  <link name="right_wheel_link">
    <inertial>
      <origin rpy="0 0 0" xyz="5.20143266670436E-06 5.37603125005695E-07 -0.0018711144360713"/>
      <mass value="1.15656808640541"/>
      <inertia ixx="0.0021044922532766" ixy="1.88606601059021E-10" ixz="-3.50324127667933E-07" iyy="0.00210448664280546" iyz="-3.619495141978E-08" izz="0.00355284737378788"/>
    </inertial>
    <visual>
      <origin rpy="0 0 0" xyz="0 0 0"/>
      <geometry>
        <mesh filename="package://mmk2_urdf/meshes/slamtec_athena/visual/right_wheel_link.STL"/>
      </geometry>
      <material name="">
        <color rgba="0.752941176470588 0.752941176470588 0.752941176470588 1"/>
      </material>
    </visual>
    <collision>
      <origin rpy="0 0 0" xyz="0 0 0"/>
      <geometry>
        <mesh filename="package://mmk2_urdf/meshes/slamtec_athena/collision/right_wheel_link.STL"/>
      </geometry>
    </collision>
  </link>
  <joint name="right_wheel_joint" type="revolute">
    <origin rpy="1.5708 1.5708 0" xyz="0 -0.16325 0.08401"/>
    <parent link="base_link"/>
    <child link="right_wheel_link"/>
    <axis xyz="0 0 1"/>
    <limit effort="6.5" lower="-3.1416" upper="3.1416" velocity="0.7"/>
  </joint>
  <link name="left_wheel_link">
    <inertial>
      <origin rpy="0 0 0" xyz="1.28756699316335E-06 -5.0575586944921E-06 0.00187111444199509"/>
      <mass value="1.15656808621832"/>
      <inertia ixx="0.00210448719172768" ixy="-1.67788115008943E-09" ixz="8.7251015028674E-08" iyy="0.00210449170378954" iyz="-3.41206350459015E-07" izz="0.00355284737380655"/>
    </inertial>
    <visual>
      <origin rpy="0 0 0" xyz="0 0 0"/>
      <geometry>
        <mesh filename="package://mmk2_urdf/meshes/slamtec_athena/visual/left_wheel_link.STL"/>
      </geometry>
      <material name="">
        <color rgba="0.752941176470588 0.752941176470588 0.752941176470588 1"/>
      </material>
    </visual>
    <collision>
      <origin rpy="0 0 0" xyz="0 0 0"/>
      <geometry>
        <mesh filename="package://mmk2_urdf/meshes/slamtec_athena/collision/left_wheel_link.STL"/>
      </geometry>
    </collision>
  </link>
  <joint name="left_wheel_joint" type="revolute">
    <origin rpy="1.5708 1.5708 0" xyz="0 0.16325 0.08401"/>
    <parent link="base_link"/>
    <child link="left_wheel_link"/>
    <axis xyz="0 0 1"/>
    <limit effort="6.5" lower="-3.1416" upper="3.1416" velocity="0.7"/>
  </joint>
  <ros2_control name="head_yaw_control" type="actuator">
    <hardware>
      <plugin>airbot_ros2_control/DmActuatorHardware</plugin>
      <param name="can_interface">can_head</param>
      <param name="motor_id">1</param>
      <param name="use_as_actuator">true</param>
      <param name="arm_sn_code">123456787654321</param>
    </hardware>
    <joint name="head_yaw_joint">
      <command_interface name="internal/position"/>
      <command_interface name="internal/velocity"/>
      <command_interface name="internal/effort"/>
      <command_interface name="internal/control_mode_command"/>
      <command_interface name="internal/max_velocity_thres"/>
      <command_interface name="internal/max_effort_thres"/>
      <command_interface name="internal/mit_kp"/>
      <command_interface name="internal/mit_kd"/>
      <state_interface name="position">
        <param name="initial_value">0.0</param>
      </state_interface>
      <state_interface name="velocity"/>
      <state_interface name="effort"/>
      <state_interface name="motor_temperature"/>
      <state_interface name="mos_temperature"/>
      <state_interface name="error_id"/>
    </joint>
  </ros2_control>
  <ros2_control name="head_pitch_control" type="actuator">
    <hardware>
      <plugin>airbot_ros2_control/DmActuatorHardware</plugin>
      <param name="can_interface">can_head</param>
      <param name="motor_id">2</param>
      <param name="use_as_actuator">true</param>
      <param name="arm_sn_code">123456787654321</param>
    </hardware>
    <joint name="head_pitch_joint">
      <command_interface name="internal/position"/>
      <command_interface name="internal/velocity"/>
      <command_interface name="internal/effort"/>
      <command_interface name="internal/control_mode_command"/>
      <command_interface name="internal/max_velocity_thres"/>
      <command_interface name="internal/max_effort_thres"/>
      <command_interface name="internal/mit_kp"/>
      <command_interface name="internal/mit_kd"/>
      <state_interface name="position">
        <param name="initial_value">0.0</param>
      </state_interface>
      <state_interface name="velocity"/>
      <state_interface name="effort"/>
      <state_interface name="motor_temperature"/>
      <state_interface name="mos_temperature"/>
      <state_interface name="error_id"/>
    </joint>
  </ros2_control>
  <ros2_control name="slide_linear_control" type="actuator">
    <hardware>
      <plugin>airbot_ros2_control/SpineActuatorPositionOnlyHardware</plugin>
      <param name="serial_port_name">/dev/spine</param>
      <param name="baud_rate">115200</param>
      <param name="slave_id">1</param>
    </hardware>
    <joint name="slide_joint">
      <command_interface name="position"/>
      <state_interface name="position">
        <param name="initial_value">0.0</param>
      </state_interface>
      <state_interface name="velocity"/>
      <state_interface name="effort"/>
    </joint>
  </ros2_control>
  <link name="left_arm_flange">
    <inertial>
      <origin rpy="0 0 0" xyz="0.007 0. 0."/>
      <mass value="0.0206"/>
      <!-- should calcullate the inertia later -->
      <inertia ixx="0.0" ixy="0.0" ixz="0.0" iyy="0.0" iyz="0.0" izz="0.0"/>
    </inertial>
    <visual>
      <origin rpy="0. -1.5707964 0. " xyz="0.0040002 0.0219004 -0.0221024"/>
      <geometry>
        <mesh filename="package://mmk2_urdf/meshes/flange/visual/flange.obj" scale="1. 1. 1."/>
      </geometry>
    </visual>
    <collision>
      <origin rpy="0. -1.5707964 0. " xyz="0.0040002 0.0219004 -0.0221024"/>
      <geometry>
        <mesh filename="package://mmk2_urdf/meshes/flange/collision/flange.obj" scale="1. 1. 1."/>
      </geometry>
    </collision>
  </link>
  <link name="left_arm_base_link">
    <inertial>
      <origin rpy="0 0 0" xyz="-0.013241649 -0.0014483907 0.037394006"/>
      <mass value="0.683"/>
      <inertia ixx="0.00056691" ixy="7.5556E-06" ixz="1.0335E-06" iyy="0.00068606" iyz="7.7985E-07" izz="0.0010143"/>
    </inertial>
    <visual>
      <origin rpy="0 0 0" xyz="0 0 0"/>
      <geometry>
        <mesh filename="package://mmk2_urdf/meshes/airbot_play_v3_1/visual/base_link.STL"/>
      </geometry>
      <material name="">
        <color rgba="0.75294 0.75294 0.75294 1"/>
      </material>
    </visual>
    <collision>
      <origin rpy="0 0 0" xyz="0 0 0"/>
      <geometry>
        <mesh filename="package://mmk2_urdf/meshes/airbot_play_v3_1/collision/base_link.STL"/>
      </geometry>
    </collision>
  </link>
  <link name="left_arm_link1">
    <inertial>
      <origin rpy="0 0 0" xyz="5.6582251E-05 -0.0025468634 -0.026016066"/>
      <mass value="0.609"/>
      <inertia ixx="0.00026059" ixy="-2.1857E-07" ixz="1.3032E-06" iyy="0.00035988" iyz="1.5738E-05" izz="0.00030082"/>
    </inertial>
    <visual>
      <origin rpy="0 0 0" xyz="0 0 0"/>
      <geometry>
        <mesh filename="package://mmk2_urdf/meshes/airbot_play_v3_1/visual/link1.STL"/>
      </geometry>
      <material name="">
        <color rgba="0.75294 0.75294 0.75294 1"/>
      </material>
    </visual>
    <collision>
      <origin rpy="0 0 0" xyz="0 0 0"/>
      <geometry>
        <mesh filename="package://mmk2_urdf/meshes/airbot_play_v3_1/collision/link1.STL"/>
      </geometry>
    </collision>
  </link>
  <joint name="left_arm_joint1" type="revolute">
    <origin rpy="0 0 0" xyz="0 0 0.1117"/>
    <parent link="left_arm_base_link"/>
    <child link="left_arm_link1"/>
    <axis xyz="0 0 1"/>
    <limit effort="12" lower="-3.151" upper="2.089" velocity="0.5"/>
  </joint>
  <link name="left_arm_link2">
    <inertial>
      <origin rpy="0 0 0" xyz="0.15031499 0.0071730548 0.0016032489"/>
      <mass value="0.902"/>
      <inertia ixx="0.00040289" ixy="-0.00012909" ixz="4.6597E-05" iyy="0.003174" iyz="9.7791E-06" izz="0.0033885"/>
    </inertial>
    <visual>
      <origin rpy="0 0 0" xyz="0 0 0"/>
      <geometry>
        <mesh filename="package://mmk2_urdf/meshes/airbot_play_v3_1/visual/link2.STL"/>
      </geometry>
      <material name="">
        <color rgba="0.75294 0.75294 0.75294 1"/>
      </material>
    </visual>
    <collision>
      <origin rpy="0 0 0" xyz="0 0 0"/>
      <geometry>
        <mesh filename="package://mmk2_urdf/meshes/airbot_play_v3_1/collision/link2.STL"/>
      </geometry>
    </collision>
  </link>
  <joint name="left_arm_joint2" type="revolute">
    <origin rpy="-1.5691 -0.38673 3.1409" xyz="0 0 0"/>
    <parent link="left_arm_link1"/>
    <child link="left_arm_link2"/>
    <axis xyz="0 0 1"/>
    <limit effort="12" lower="-2.963" upper="0.181" velocity="0.5"/>
  </joint>
  <link name="left_arm_link3">
    <inertial>
      <origin rpy="0 0 0" xyz="2.8745009E-05 0.11006382 0.0042664091"/>
      <mass value="0.683"/>
      <inertia ixx="0.0011117" ixy="2.9694E-07" ixz="-1.1205E-07" iyy="0.00022817" iyz="0.00014247" izz="0.0011062"/>
    </inertial>
    <visual>
      <origin rpy="0 0 0" xyz="0 0 0"/>
      <geometry>
        <mesh filename="package://mmk2_urdf/meshes/airbot_play_v3_1/visual/link3.STL"/>
      </geometry>
      <material name="">
        <color rgba="0.75294 0.75294 0.75294 1"/>
      </material>
    </visual>
    <collision>
      <origin rpy="0 0 0" xyz="0 0 0"/>
      <geometry>
        <mesh filename="package://mmk2_urdf/meshes/airbot_play_v3_1/collision/link3.STL"/>
      </geometry>
    </collision>
  </link>
  <joint name="left_arm_joint3" type="revolute">
    <origin rpy="0 0.0015895 1.9575" xyz="0.27009 0 0"/>
    <parent link="left_arm_link2"/>
    <child link="left_arm_link3"/>
    <axis xyz="0 0 1"/>
    <limit effort="12" lower="-0.094" upper="3.161" velocity="0.5"/>
  </joint>
  <link name="left_arm_link4">
    <inertial>
      <origin rpy="0 0 0" xyz="-4.3875215E-05 0.00050280749 -0.020529025"/>
      <mass value="0.358"/>
      <inertia ixx="0.00011024" ixy="6.4278E-09" ixz="-5.8907E-08" iyy="0.00013798" iyz="-7.8592E-06" izz="0.00011351"/>
    </inertial>
    <visual>
      <origin rpy="0 0 0" xyz="0 0 0"/>
      <geometry>
        <mesh filename="package://mmk2_urdf/meshes/airbot_play_v3_1/visual/link4.STL"/>
      </geometry>
      <material name="">
        <color rgba="0.75294 0.75294 0.75294 1"/>
      </material>
    </visual>
    <collision>
      <origin rpy="0 0 0" xyz="0 0 0"/>
      <geometry>
        <mesh filename="package://mmk2_urdf/meshes/airbot_play_v3_1/collision/link4.STL"/>
      </geometry>
    </collision>
  </link>
  <joint name="left_arm_joint4" type="revolute">
    <origin rpy="-1.5708 -1.5708 0" xyz="8.2128E-05 0.29015 0"/>
    <parent link="left_arm_link3"/>
    <child link="left_arm_link4"/>
    <axis xyz="0 0 1"/>
    <limit effort="3" lower="-3.012" upper="3.012" velocity="1"/>
  </joint>
  <link name="left_arm_link5">
    <inertial>
      <origin rpy="0 0 0" xyz="1.0725637E-04 0.037609585 0.00094283927"/>
      <mass value="0.403"/>
      <inertia ixx="0.00014324" ixy="-1.2363E-07" ixz="-1.6092E-07" iyy="0.00015285" iyz="1.3894E-05" izz="0.00014936"/>
    </inertial>
    <visual>
      <origin rpy="0 0 0" xyz="0 0 0"/>
      <geometry>
        <mesh filename="package://mmk2_urdf/meshes/airbot_play_v3_1/visual/link5.STL"/>
      </geometry>
      <material name="">
        <color rgba="0.75294 0.75294 0.75294 1"/>
      </material>
    </visual>
    <collision>
      <origin rpy="0 0 0" xyz="0 0 0"/>
      <geometry>
        <mesh filename="package://mmk2_urdf/meshes/airbot_play_v3_1/collision/link5.STL"/>
      </geometry>
    </collision>
  </link>
  <joint name="left_arm_joint5" type="revolute">
    <origin rpy="1.5708 0 0" xyz="0 0 0"/>
    <parent link="left_arm_link4"/>
    <child link="left_arm_link5"/>
    <axis xyz="0 0 1"/>
    <limit effort="3" lower="-1.859" upper="1.859" velocity="1"/>
  </joint>
  <link name="left_arm_link6">
    <inertial>
      <origin rpy="0 0 0" xyz="-0.022 0 0"/>
      <mass value="0.118"/>
      <inertia ixx="2.3175E-05" ixy="-8.0893E-10" ixz="-2.5166E-14" iyy="1.2978E-05" iyz="-2.9196E-09" izz="1.2976E-05"/>
    </inertial>
    <visual>
      <origin rpy="0 0 0" xyz="0 0 0"/>
      <geometry>
        <mesh filename="package://mmk2_urdf/meshes/airbot_play_v3_1/visual/link6.STL"/>
      </geometry>
      <material name="">
        <color rgba="0.75294 0.75294 0.75294 1"/>
      </material>
    </visual>
    <collision>
      <origin rpy="0 0 0" xyz="0 0 0"/>
      <geometry>
        <mesh filename="package://mmk2_urdf/meshes/airbot_play_v3_1/collision/link6.STL"/>
      </geometry>
    </collision>
  </link>
  <joint name="left_arm_joint6" type="revolute">
    <origin rpy="0 0 1.5708" xyz="0 0.0864 0"/>
    <parent link="left_arm_link5"/>
    <child link="left_arm_link6"/>
    <axis xyz="1 0 0"/>
    <limit effort="3" lower="-3.017" upper="3.017" velocity="1"/>
  </joint>
  <joint name="left_arm_arm_to_flange" type="fixed">
    <origin rpy="0 0 0" xyz="0 0 0"/>
    <parent link="left_arm_link6"/>
    <child link="left_arm_flange"/>
  </joint>
  <ros2_control name="left_arm_airbot_play_ros2_control" type="system">
    <hardware>
      <plugin>airbot_ros2_control/AirbotSystemHardware</plugin>
      <param name="can_interface">can_left</param>
      <param name="prefix">left_arm_</param>
      <param name="arm_type">play_short</param>
      <param name="od_motor_num">3</param>
      <param name="dm_motor_num">3</param>
      <param name="arm_sn_code">123456787654321</param>
    </hardware>
    <joint name="left_arm_joint1">
      <command_interface name="internal/position">
        <param name="min">-6.283185307179586</param>
        <param name="max">2.09</param>
      </command_interface>
      <command_interface name="internal/velocity">
        <param name="min">-3.15</param>
        <param name="max">3.15</param>
      </command_interface>
      <command_interface name="internal/effort">
        <param name="min">-18</param>
        <param name="max">18</param>
      </command_interface>
      <command_interface name="internal/control_mode_command"/>
      <command_interface name="internal/max_velocity_thres"/>
      <command_interface name="internal/max_effort_thres"/>
      <command_interface name="internal/mit_kp"/>
      <command_interface name="internal/mit_kd"/>
      <state_interface name="position">
        <param name="initial_value">0.0</param>
      </state_interface>
      <state_interface name="velocity"/>
      <state_interface name="effort"/>
      <state_interface name="motor_temperature"/>
      <state_interface name="mos_temperature"/>
      <state_interface name="error_id"/>
    </joint>
    <joint name="left_arm_joint2">
      <command_interface name="internal/position">
        <param name="min">-2.96</param>
        <param name="max">0.17</param>
      </command_interface>
      <command_interface name="internal/velocity">
        <param name="min">-3.15</param>
        <param name="max">3.15</param>
      </command_interface>
      <command_interface name="internal/effort">
        <param name="min">-18</param>
        <param name="max">18</param>
      </command_interface>
      <command_interface name="internal/control_mode_command"/>
      <command_interface name="internal/max_velocity_thres"/>
      <command_interface name="internal/max_effort_thres"/>
      <command_interface name="internal/mit_kp"/>
      <command_interface name="internal/mit_kd"/>
      <state_interface name="position">
        <param name="initial_value">0.0</param>
      </state_interface>
      <state_interface name="velocity"/>
      <state_interface name="effort"/>
      <state_interface name="motor_temperature"/>
      <state_interface name="mos_temperature"/>
      <state_interface name="error_id"/>
    </joint>
    <joint name="left_arm_joint3">
      <command_interface name="internal/position">
        <param name="min">-0.087</param>
        <param name="max">3.141592653589793</param>
      </command_interface>
      <command_interface name="internal/velocity">
        <param name="min">-3.15</param>
        <param name="max">3.15</param>
      </command_interface>
      <command_interface name="internal/effort">
        <param name="min">-18</param>
        <param name="max">18</param>
      </command_interface>
      <command_interface name="internal/control_mode_command"/>
      <command_interface name="internal/max_velocity_thres"/>
      <command_interface name="internal/max_effort_thres"/>
      <command_interface name="internal/mit_kp"/>
      <command_interface name="internal/mit_kd"/>
      <state_interface name="position">
        <param name="initial_value">0.0</param>
      </state_interface>
      <state_interface name="velocity"/>
      <state_interface name="effort"/>
      <state_interface name="motor_temperature"/>
      <state_interface name="mos_temperature"/>
      <state_interface name="error_id"/>
    </joint>
    <joint name="left_arm_joint4">
      <command_interface name="internal/position">
        <param name="min">-2.96</param>
        <param name="max">2.96</param>
      </command_interface>
      <command_interface name="internal/velocity">
        <param name="min">-3.2</param>
        <param name="max">3.2</param>
      </command_interface>
      <command_interface name="internal/effort">
        <param name="min">-3</param>
        <param name="max">3</param>
      </command_interface>
      <command_interface name="internal/control_mode_command"/>
      <command_interface name="internal/max_velocity_thres"/>
      <command_interface name="internal/max_effort_thres"/>
      <command_interface name="internal/mit_kp"/>
      <command_interface name="internal/mit_kd"/>
      <state_interface name="position">
        <param name="initial_value">0.0</param>
      </state_interface>
      <state_interface name="velocity"/>
      <state_interface name="effort"/>
      <state_interface name="motor_temperature"/>
      <state_interface name="mos_temperature"/>
      <state_interface name="error_id"/>
    </joint>
    <joint name="left_arm_joint5">
      <command_interface name="internal/position">
        <param name="min">-1.5707963267948966</param>
        <param name="max">1.5707963267948966</param>
      </command_interface>
      <command_interface name="internal/velocity">
        <param name="min">-6.283185307179586</param>
        <param name="max">6.283185307179586</param>
      </command_interface>
      <command_interface name="internal/effort">
        <param name="min">-3</param>
        <param name="max">3</param>
      </command_interface>
      <command_interface name="internal/control_mode_command"/>
      <command_interface name="internal/max_velocity_thres"/>
      <command_interface name="internal/max_effort_thres"/>
      <command_interface name="internal/mit_kp"/>
      <command_interface name="internal/mit_kd"/>
      <state_interface name="position">
        <param name="initial_value">0.0</param>
      </state_interface>
      <state_interface name="velocity"/>
      <state_interface name="effort"/>
      <state_interface name="motor_temperature"/>
      <state_interface name="mos_temperature"/>
      <state_interface name="error_id"/>
    </joint>
    <joint name="left_arm_joint6">
      <command_interface name="internal/position">
        <param name="min">-3.141592653589793</param>
        <param name="max">3.141592653589793</param>
      </command_interface>
      <command_interface name="internal/velocity">
        <param name="min">-6.283185307179586</param>
        <param name="max">6.283185307179586</param>
      </command_interface>
      <command_interface name="internal/effort">
        <param name="min">-3</param>
        <param name="max">3</param>
      </command_interface>
      <command_interface name="internal/control_mode_command"/>
      <command_interface name="internal/max_velocity_thres"/>
      <command_interface name="internal/max_effort_thres"/>
      <command_interface name="internal/mit_kp"/>
      <command_interface name="internal/mit_kd"/>
      <state_interface name="position">
        <param name="initial_value">0.0</param>
      </state_interface>
      <state_interface name="velocity"/>
      <state_interface name="effort"/>
      <state_interface name="motor_temperature"/>
      <state_interface name="mos_temperature"/>
      <state_interface name="error_id"/>
    </joint>
    <gpio name="left_arm_base_led">
      <command_interface name="led_mode"/>
      <state_interface name="led_mode"/>
    </gpio>
    <gpio name="left_arm_buttons">
      <state_interface name="base_button"/>
      <state_interface name="end_button"/>
    </gpio>
  </ros2_control>
  <link name="left_arm_eef_G2_base_link">
    <inertial>
      <origin rpy="0 0 0" xyz="0.046303 -9.8611E-06 -1.4675E-05"/>
      <mass value="0.26507"/>
      <inertia ixx="348.3689417" ixy="0.2800965" ixz="-0.0560724" iyy="198.5351968" iyz="1.3076668" izz="449.2281738"/>
    </inertial>
    <visual>
      <origin rpy="0 0 0" xyz="0 0 0"/>
      <geometry>
        <mesh filename="package://mmk2_urdf/meshes/G2/visual/base_link.STL"/>
      </geometry>
      <material name="">
        <color rgba="0.75294 0.75294 0.75294 1"/>
      </material>
    </visual>
    <collision>
      <origin rpy="0 0 0" xyz="0 0 0"/>
      <geometry>
        <mesh filename="package://mmk2_urdf/meshes/G2/collision/base_link.STL"/>
      </geometry>
    </collision>
  </link>
  <link name="left_arm_eef_G2_link1">
    <inertial>
      <origin rpy="0 0 0" xyz="-0.015415 -0.066964 0.014312"/>
      <mass value="0.078003"/>
      <inertia ixx="34.1905834" ixy="-0.1388713" ixz="-0.4368816" iyy="54.1781125" iyz="6.8453757" izz="27.3518738"/>
    </inertial>
    <visual>
      <origin rpy="0 0 0" xyz="0 0 0"/>
      <geometry>
        <mesh filename="package://mmk2_urdf/meshes/G2/visual/link1.STL"/>
      </geometry>
      <material name="">
        <color rgba="0.75294 0.75294 0.75294 1"/>
      </material>
    </visual>
    <collision>
      <origin rpy="0 0 0" xyz="0 0 0"/>
      <geometry>
        <mesh filename="package://mmk2_urdf/meshes/G2/collision/link1.STL"/>
      </geometry>
    </collision>
  </link>
  <joint name="left_arm_eef_G2_joint1" type="prismatic">
    <origin rpy="0 1.5708 0" xyz="0.0736 0.05 -0.015"/>
    <parent link="left_arm_eef_G2_base_link"/>
    <child link="left_arm_eef_G2_link1"/>
    <axis xyz="0 1 0"/>
    <limit effort="3" lower="-0.034" upper="0" velocity="1"/>
    <mimic joint="left_arm_eef_gripper_joint" multiplier="-0.034" offset="0"/>
  </joint>
  <link name="left_arm_eef_G2_link2">
    <inertial>
      <origin rpy="0 0 0" xyz="-0.014585 0.066964 0.014312"/>
      <mass value="0.078003"/>
      <inertia ixx="34.1905834" ixy="-0.1388713" ixz="0.4368816" iyy="54.1781125" iyz="-6.8453757" izz="27.3518738"/>
    </inertial>
    <visual>
      <origin rpy="0 0 0" xyz="0 0 0"/>
      <geometry>
        <mesh filename="package://mmk2_urdf/meshes/G2/visual/link2.STL"/>
      </geometry>
      <material name="">
        <color rgba="0.75294 0.75294 0.75294 1"/>
      </material>
    </visual>
    <collision>
      <origin rpy="0 0 0" xyz="0 0 0"/>
      <geometry>
        <mesh filename="package://mmk2_urdf/meshes/G2/collision/link2.STL"/>
      </geometry>
    </collision>
  </link>
  <joint name="left_arm_eef_G2_joint2" type="prismatic">
    <origin rpy="0 1.5708 0" xyz="0.0736 -0.05 -0.015"/>
    <parent link="left_arm_eef_G2_base_link"/>
    <child link="left_arm_eef_G2_link2"/>
    <axis xyz="0 1 0"/>
    <limit effort="3" lower="0" upper="0.034" velocity="1"/>
    <mimic joint="left_arm_eef_gripper_joint" multiplier="0.034" offset="0"/>
  </joint>
  <joint name="left_arm_eef_gripper_joint" type="revolute">
    <origin rpy="0 0 0" xyz="0 0 0"/>
    <axis xyz="0 0 1"/>
    <parent link="left_arm_eef_G2_base_link"/>
    <child link="left_arm_eef_rotate_motor"/>
    <limit effort="20" lower="0" upper="1" velocity="3.1415926"/>
  </joint>
  <link name="left_arm_eef_rotate_motor"/>
  <joint name="left_arm_gripper_connector" type="fixed">
    <origin rpy="0 0 0" xyz="0.009 0 0"/>
    <parent link="left_arm_flange"/>
    <child link="left_arm_eef_G2_base_link"/>
  </joint>
  <link name="left_arm_end_link">
    <inertial>
      <origin rpy="0 0 0" xyz="-0.104492 0 0"/>
      <mass value="0.605"/>
      <inertia ixx="0.0003483689417" ixy="0.0000002800965" ixz="-0.0000000560724" iyy="0.0070013022796" iyz="0.0000013076668" izz="0.007251995256600001"/>
    </inertial>
  </link>
  <joint name="left_arm_eef_end_joint" type="fixed">
    <origin rpy="0 0 0" xyz="0.1602 0 0"/>
    <parent link="left_arm_flange"/>
    <child link="left_arm_end_link"/>
  </joint>
  <ros2_control name="left_arm_eef_eef_ros2_control" type="actuator">
    <hardware>
      <plugin>airbot_ros2_control/DmActuatorHardware</plugin>
      <param name="can_interface">can_left</param>
      <param name="motor_id">7</param>
      <param name="use_as_actuator">true</param>
      <param name="is_pos_normalized">true</param>
      <param name="upper_limit">-1.6</param>
      <param name="lower_limit">0</param>
    </hardware>
    <joint name="left_arm_eef_gripper_joint">
      <command_interface name="internal/position">
          </command_interface>
      <command_interface name="internal/velocity">
          </command_interface>
      <command_interface name="internal/effort">
          </command_interface>
      <command_interface name="internal/control_mode_command"/>
      <command_interface name="internal/max_velocity_thres"/>
      <command_interface name="internal/max_effort_thres"/>
      <command_interface name="internal/mit_kp"/>
      <command_interface name="internal/mit_kd"/>
      <state_interface name="position">
        <param name="initial_value">0.0</param>
      </state_interface>
      <state_interface name="velocity"/>
      <state_interface name="effort"/>
      <state_interface name="motor_temperature"/>
      <state_interface name="mos_temperature"/>
      <state_interface name="error_id"/>
    </joint>
  </ros2_control>
  <link name="right_arm_flange">
    <inertial>
      <origin rpy="0 0 0" xyz="0.007 0. 0."/>
      <mass value="0.0206"/>
      <!-- should calcullate the inertia later -->
      <inertia ixx="0.0" ixy="0.0" ixz="0.0" iyy="0.0" iyz="0.0" izz="0.0"/>
    </inertial>
    <visual>
      <origin rpy="0. -1.5707964 0. " xyz="0.0040002 0.0219004 -0.0221024"/>
      <geometry>
        <mesh filename="package://mmk2_urdf/meshes/flange/visual/flange.obj" scale="1. 1. 1."/>
      </geometry>
    </visual>
    <collision>
      <origin rpy="0. -1.5707964 0. " xyz="0.0040002 0.0219004 -0.0221024"/>
      <geometry>
        <mesh filename="package://mmk2_urdf/meshes/flange/collision/flange.obj" scale="1. 1. 1."/>
      </geometry>
    </collision>
  </link>
  <link name="right_arm_base_link">
    <inertial>
      <origin rpy="0 0 0" xyz="-0.013241649 -0.0014483907 0.037394006"/>
      <mass value="0.683"/>
      <inertia ixx="0.00056691" ixy="7.5556E-06" ixz="1.0335E-06" iyy="0.00068606" iyz="7.7985E-07" izz="0.0010143"/>
    </inertial>
    <visual>
      <origin rpy="0 0 0" xyz="0 0 0"/>
      <geometry>
        <mesh filename="package://mmk2_urdf/meshes/airbot_play_v3_1/visual/base_link.STL"/>
      </geometry>
      <material name="">
        <color rgba="0.75294 0.75294 0.75294 1"/>
      </material>
    </visual>
    <collision>
      <origin rpy="0 0 0" xyz="0 0 0"/>
      <geometry>
        <mesh filename="package://mmk2_urdf/meshes/airbot_play_v3_1/collision/base_link.STL"/>
      </geometry>
    </collision>
  </link>
  <link name="right_arm_link1">
    <inertial>
      <origin rpy="0 0 0" xyz="5.6582251E-05 -0.0025468634 -0.026016066"/>
      <mass value="0.609"/>
      <inertia ixx="0.00026059" ixy="-2.1857E-07" ixz="1.3032E-06" iyy="0.00035988" iyz="1.5738E-05" izz="0.00030082"/>
    </inertial>
    <visual>
      <origin rpy="0 0 0" xyz="0 0 0"/>
      <geometry>
        <mesh filename="package://mmk2_urdf/meshes/airbot_play_v3_1/visual/link1.STL"/>
      </geometry>
      <material name="">
        <color rgba="0.75294 0.75294 0.75294 1"/>
      </material>
    </visual>
    <collision>
      <origin rpy="0 0 0" xyz="0 0 0"/>
      <geometry>
        <mesh filename="package://mmk2_urdf/meshes/airbot_play_v3_1/collision/link1.STL"/>
      </geometry>
    </collision>
  </link>
  <joint name="right_arm_joint1" type="revolute">
    <origin rpy="0 0 0" xyz="0 0 0.1117"/>
    <parent link="right_arm_base_link"/>
    <child link="right_arm_link1"/>
    <axis xyz="0 0 1"/>
    <limit effort="12" lower="-3.151" upper="2.089" velocity="0.5"/>
  </joint>
  <link name="right_arm_link2">
    <inertial>
      <origin rpy="0 0 0" xyz="0.15031499 0.0071730548 0.0016032489"/>
      <mass value="0.902"/>
      <inertia ixx="0.00040289" ixy="-0.00012909" ixz="4.6597E-05" iyy="0.003174" iyz="9.7791E-06" izz="0.0033885"/>
    </inertial>
    <visual>
      <origin rpy="0 0 0" xyz="0 0 0"/>
      <geometry>
        <mesh filename="package://mmk2_urdf/meshes/airbot_play_v3_1/visual/link2.STL"/>
      </geometry>
      <material name="">
        <color rgba="0.75294 0.75294 0.75294 1"/>
      </material>
    </visual>
    <collision>
      <origin rpy="0 0 0" xyz="0 0 0"/>
      <geometry>
        <mesh filename="package://mmk2_urdf/meshes/airbot_play_v3_1/collision/link2.STL"/>
      </geometry>
    </collision>
  </link>
  <joint name="right_arm_joint2" type="revolute">
    <origin rpy="-1.5691 -0.38673 3.1409" xyz="0 0 0"/>
    <parent link="right_arm_link1"/>
    <child link="right_arm_link2"/>
    <axis xyz="0 0 1"/>
    <limit effort="12" lower="-2.963" upper="0.181" velocity="0.5"/>
  </joint>
  <link name="right_arm_link3">
    <inertial>
      <origin rpy="0 0 0" xyz="2.8745009E-05 0.11006382 0.0042664091"/>
      <mass value="0.683"/>
      <inertia ixx="0.0011117" ixy="2.9694E-07" ixz="-1.1205E-07" iyy="0.00022817" iyz="0.00014247" izz="0.0011062"/>
    </inertial>
    <visual>
      <origin rpy="0 0 0" xyz="0 0 0"/>
      <geometry>
        <mesh filename="package://mmk2_urdf/meshes/airbot_play_v3_1/visual/link3.STL"/>
      </geometry>
      <material name="">
        <color rgba="0.75294 0.75294 0.75294 1"/>
      </material>
    </visual>
    <collision>
      <origin rpy="0 0 0" xyz="0 0 0"/>
      <geometry>
        <mesh filename="package://mmk2_urdf/meshes/airbot_play_v3_1/collision/link3.STL"/>
      </geometry>
    </collision>
  </link>
  <joint name="right_arm_joint3" type="revolute">
    <origin rpy="0 0.0015895 1.9575" xyz="0.27009 0 0"/>
    <parent link="right_arm_link2"/>
    <child link="right_arm_link3"/>
    <axis xyz="0 0 1"/>
    <limit effort="12" lower="-0.094" upper="3.161" velocity="0.5"/>
  </joint>
  <link name="right_arm_link4">
    <inertial>
      <origin rpy="0 0 0" xyz="-4.3875215E-05 0.00050280749 -0.020529025"/>
      <mass value="0.358"/>
      <inertia ixx="0.00011024" ixy="6.4278E-09" ixz="-5.8907E-08" iyy="0.00013798" iyz="-7.8592E-06" izz="0.00011351"/>
    </inertial>
    <visual>
      <origin rpy="0 0 0" xyz="0 0 0"/>
      <geometry>
        <mesh filename="package://mmk2_urdf/meshes/airbot_play_v3_1/visual/link4.STL"/>
      </geometry>
      <material name="">
        <color rgba="0.75294 0.75294 0.75294 1"/>
      </material>
    </visual>
    <collision>
      <origin rpy="0 0 0" xyz="0 0 0"/>
      <geometry>
        <mesh filename="package://mmk2_urdf/meshes/airbot_play_v3_1/collision/link4.STL"/>
      </geometry>
    </collision>
  </link>
  <joint name="right_arm_joint4" type="revolute">
    <origin rpy="-1.5708 -1.5708 0" xyz="8.2128E-05 0.29015 0"/>
    <parent link="right_arm_link3"/>
    <child link="right_arm_link4"/>
    <axis xyz="0 0 1"/>
    <limit effort="3" lower="-3.012" upper="3.012" velocity="1"/>
  </joint>
  <link name="right_arm_link5">
    <inertial>
      <origin rpy="0 0 0" xyz="1.0725637E-04 0.037609585 0.00094283927"/>
      <mass value="0.403"/>
      <inertia ixx="0.00014324" ixy="-1.2363E-07" ixz="-1.6092E-07" iyy="0.00015285" iyz="1.3894E-05" izz="0.00014936"/>
    </inertial>
    <visual>
      <origin rpy="0 0 0" xyz="0 0 0"/>
      <geometry>
        <mesh filename="package://mmk2_urdf/meshes/airbot_play_v3_1/visual/link5.STL"/>
      </geometry>
      <material name="">
        <color rgba="0.75294 0.75294 0.75294 1"/>
      </material>
    </visual>
    <collision>
      <origin rpy="0 0 0" xyz="0 0 0"/>
      <geometry>
        <mesh filename="package://mmk2_urdf/meshes/airbot_play_v3_1/collision/link5.STL"/>
      </geometry>
    </collision>
  </link>
  <joint name="right_arm_joint5" type="revolute">
    <origin rpy="1.5708 0 0" xyz="0 0 0"/>
    <parent link="right_arm_link4"/>
    <child link="right_arm_link5"/>
    <axis xyz="0 0 1"/>
    <limit effort="3" lower="-1.859" upper="1.859" velocity="1"/>
  </joint>
  <link name="right_arm_link6">
    <inertial>
      <origin rpy="0 0 0" xyz="-0.022 0 0"/>
      <mass value="0.118"/>
      <inertia ixx="2.3175E-05" ixy="-8.0893E-10" ixz="-2.5166E-14" iyy="1.2978E-05" iyz="-2.9196E-09" izz="1.2976E-05"/>
    </inertial>
    <visual>
      <origin rpy="0 0 0" xyz="0 0 0"/>
      <geometry>
        <mesh filename="package://mmk2_urdf/meshes/airbot_play_v3_1/visual/link6.STL"/>
      </geometry>
      <material name="">
        <color rgba="0.75294 0.75294 0.75294 1"/>
      </material>
    </visual>
    <collision>
      <origin rpy="0 0 0" xyz="0 0 0"/>
      <geometry>
        <mesh filename="package://mmk2_urdf/meshes/airbot_play_v3_1/collision/link6.STL"/>
      </geometry>
    </collision>
  </link>
  <joint name="right_arm_joint6" type="revolute">
    <origin rpy="0 0 1.5708" xyz="0 0.0864 0"/>
    <parent link="right_arm_link5"/>
    <child link="right_arm_link6"/>
    <axis xyz="1 0 0"/>
    <limit effort="3" lower="-3.017" upper="3.017" velocity="1"/>
  </joint>
  <joint name="right_arm_arm_to_flange" type="fixed">
    <origin rpy="0 0 0" xyz="0 0 0"/>
    <parent link="right_arm_link6"/>
    <child link="right_arm_flange"/>
  </joint>
  <ros2_control name="right_arm_airbot_play_ros2_control" type="system">
    <hardware>
      <plugin>airbot_ros2_control/AirbotSystemHardware</plugin>
      <param name="can_interface">can_right</param>
      <param name="prefix">right_arm_</param>
      <param name="arm_type">play_short</param>
      <param name="od_motor_num">3</param>
      <param name="dm_motor_num">3</param>
      <param name="arm_sn_code">123456787654321</param>
    </hardware>
    <joint name="right_arm_joint1">
      <command_interface name="internal/position">
        <param name="min">-6.283185307179586</param>
        <param name="max">2.09</param>
      </command_interface>
      <command_interface name="internal/velocity">
        <param name="min">-3.15</param>
        <param name="max">3.15</param>
      </command_interface>
      <command_interface name="internal/effort">
        <param name="min">-18</param>
        <param name="max">18</param>
      </command_interface>
      <command_interface name="internal/control_mode_command"/>
      <command_interface name="internal/max_velocity_thres"/>
      <command_interface name="internal/max_effort_thres"/>
      <command_interface name="internal/mit_kp"/>
      <command_interface name="internal/mit_kd"/>
      <state_interface name="position">
        <param name="initial_value">0.0</param>
      </state_interface>
      <state_interface name="velocity"/>
      <state_interface name="effort"/>
      <state_interface name="motor_temperature"/>
      <state_interface name="mos_temperature"/>
      <state_interface name="error_id"/>
    </joint>
    <joint name="right_arm_joint2">
      <command_interface name="internal/position">
        <param name="min">-2.96</param>
        <param name="max">0.17</param>
      </command_interface>
      <command_interface name="internal/velocity">
        <param name="min">-3.15</param>
        <param name="max">3.15</param>
      </command_interface>
      <command_interface name="internal/effort">
        <param name="min">-18</param>
        <param name="max">18</param>
      </command_interface>
      <command_interface name="internal/control_mode_command"/>
      <command_interface name="internal/max_velocity_thres"/>
      <command_interface name="internal/max_effort_thres"/>
      <command_interface name="internal/mit_kp"/>
      <command_interface name="internal/mit_kd"/>
      <state_interface name="position">
        <param name="initial_value">0.0</param>
      </state_interface>
      <state_interface name="velocity"/>
      <state_interface name="effort"/>
      <state_interface name="motor_temperature"/>
      <state_interface name="mos_temperature"/>
      <state_interface name="error_id"/>
    </joint>
    <joint name="right_arm_joint3">
      <command_interface name="internal/position">
        <param name="min">-0.087</param>
        <param name="max">3.141592653589793</param>
      </command_interface>
      <command_interface name="internal/velocity">
        <param name="min">-3.15</param>
        <param name="max">3.15</param>
      </command_interface>
      <command_interface name="internal/effort">
        <param name="min">-18</param>
        <param name="max">18</param>
      </command_interface>
      <command_interface name="internal/control_mode_command"/>
      <command_interface name="internal/max_velocity_thres"/>
      <command_interface name="internal/max_effort_thres"/>
      <command_interface name="internal/mit_kp"/>
      <command_interface name="internal/mit_kd"/>
      <state_interface name="position">
        <param name="initial_value">0.0</param>
      </state_interface>
      <state_interface name="velocity"/>
      <state_interface name="effort"/>
      <state_interface name="motor_temperature"/>
      <state_interface name="mos_temperature"/>
      <state_interface name="error_id"/>
    </joint>
    <joint name="right_arm_joint4">
      <command_interface name="internal/position">
        <param name="min">-2.96</param>
        <param name="max">2.96</param>
      </command_interface>
      <command_interface name="internal/velocity">
        <param name="min">-3.2</param>
        <param name="max">3.2</param>
      </command_interface>
      <command_interface name="internal/effort">
        <param name="min">-3</param>
        <param name="max">3</param>
      </command_interface>
      <command_interface name="internal/control_mode_command"/>
      <command_interface name="internal/max_velocity_thres"/>
      <command_interface name="internal/max_effort_thres"/>
      <command_interface name="internal/mit_kp"/>
      <command_interface name="internal/mit_kd"/>
      <state_interface name="position">
        <param name="initial_value">0.0</param>
      </state_interface>
      <state_interface name="velocity"/>
      <state_interface name="effort"/>
      <state_interface name="motor_temperature"/>
      <state_interface name="mos_temperature"/>
      <state_interface name="error_id"/>
    </joint>
    <joint name="right_arm_joint5">
      <command_interface name="internal/position">
        <param name="min">-1.5707963267948966</param>
        <param name="max">1.5707963267948966</param>
      </command_interface>
      <command_interface name="internal/velocity">
        <param name="min">-6.283185307179586</param>
        <param name="max">6.283185307179586</param>
      </command_interface>
      <command_interface name="internal/effort">
        <param name="min">-3</param>
        <param name="max">3</param>
      </command_interface>
      <command_interface name="internal/control_mode_command"/>
      <command_interface name="internal/max_velocity_thres"/>
      <command_interface name="internal/max_effort_thres"/>
      <command_interface name="internal/mit_kp"/>
      <command_interface name="internal/mit_kd"/>
      <state_interface name="position">
        <param name="initial_value">0.0</param>
      </state_interface>
      <state_interface name="velocity"/>
      <state_interface name="effort"/>
      <state_interface name="motor_temperature"/>
      <state_interface name="mos_temperature"/>
      <state_interface name="error_id"/>
    </joint>
    <joint name="right_arm_joint6">
      <command_interface name="internal/position">
        <param name="min">-3.141592653589793</param>
        <param name="max">3.141592653589793</param>
      </command_interface>
      <command_interface name="internal/velocity">
        <param name="min">-6.283185307179586</param>
        <param name="max">6.283185307179586</param>
      </command_interface>
      <command_interface name="internal/effort">
        <param name="min">-3</param>
        <param name="max">3</param>
      </command_interface>
      <command_interface name="internal/control_mode_command"/>
      <command_interface name="internal/max_velocity_thres"/>
      <command_interface name="internal/max_effort_thres"/>
      <command_interface name="internal/mit_kp"/>
      <command_interface name="internal/mit_kd"/>
      <state_interface name="position">
        <param name="initial_value">0.0</param>
      </state_interface>
      <state_interface name="velocity"/>
      <state_interface name="effort"/>
      <state_interface name="motor_temperature"/>
      <state_interface name="mos_temperature"/>
      <state_interface name="error_id"/>
    </joint>
    <gpio name="right_arm_base_led">
      <command_interface name="led_mode"/>
      <state_interface name="led_mode"/>
    </gpio>
    <gpio name="right_arm_buttons">
      <state_interface name="base_button"/>
      <state_interface name="end_button"/>
    </gpio>
  </ros2_control>
  <link name="right_arm_eef_G2_base_link">
    <inertial>
      <origin rpy="0 0 0" xyz="0.046303 -9.8611E-06 -1.4675E-05"/>
      <mass value="0.26507"/>
      <inertia ixx="348.3689417" ixy="0.2800965" ixz="-0.0560724" iyy="198.5351968" iyz="1.3076668" izz="449.2281738"/>
    </inertial>
    <visual>
      <origin rpy="0 0 0" xyz="0 0 0"/>
      <geometry>
        <mesh filename="package://mmk2_urdf/meshes/G2/visual/base_link.STL"/>
      </geometry>
      <material name="">
        <color rgba="0.75294 0.75294 0.75294 1"/>
      </material>
    </visual>
    <collision>
      <origin rpy="0 0 0" xyz="0 0 0"/>
      <geometry>
        <mesh filename="package://mmk2_urdf/meshes/G2/collision/base_link.STL"/>
      </geometry>
    </collision>
  </link>
  <link name="right_arm_eef_G2_link1">
    <inertial>
      <origin rpy="0 0 0" xyz="-0.015415 -0.066964 0.014312"/>
      <mass value="0.078003"/>
      <inertia ixx="34.1905834" ixy="-0.1388713" ixz="-0.4368816" iyy="54.1781125" iyz="6.8453757" izz="27.3518738"/>
    </inertial>
    <visual>
      <origin rpy="0 0 0" xyz="0 0 0"/>
      <geometry>
        <mesh filename="package://mmk2_urdf/meshes/G2/visual/link1.STL"/>
      </geometry>
      <material name="">
        <color rgba="0.75294 0.75294 0.75294 1"/>
      </material>
    </visual>
    <collision>
      <origin rpy="0 0 0" xyz="0 0 0"/>
      <geometry>
        <mesh filename="package://mmk2_urdf/meshes/G2/collision/link1.STL"/>
      </geometry>
    </collision>
  </link>
  <joint name="right_arm_eef_G2_joint1" type="prismatic">
    <origin rpy="0 1.5708 0" xyz="0.0736 0.05 -0.015"/>
    <parent link="right_arm_eef_G2_base_link"/>
    <child link="right_arm_eef_G2_link1"/>
    <axis xyz="0 1 0"/>
    <limit effort="3" lower="-0.034" upper="0" velocity="1"/>
    <mimic joint="right_arm_eef_gripper_joint" multiplier="-0.034" offset="0"/>
  </joint>
  <link name="right_arm_eef_G2_link2">
    <inertial>
      <origin rpy="0 0 0" xyz="-0.014585 0.066964 0.014312"/>
      <mass value="0.078003"/>
      <inertia ixx="34.1905834" ixy="-0.1388713" ixz="0.4368816" iyy="54.1781125" iyz="-6.8453757" izz="27.3518738"/>
    </inertial>
    <visual>
      <origin rpy="0 0 0" xyz="0 0 0"/>
      <geometry>
        <mesh filename="package://mmk2_urdf/meshes/G2/visual/link2.STL"/>
      </geometry>
      <material name="">
        <color rgba="0.75294 0.75294 0.75294 1"/>
      </material>
    </visual>
    <collision>
      <origin rpy="0 0 0" xyz="0 0 0"/>
      <geometry>
        <mesh filename="package://mmk2_urdf/meshes/G2/collision/link2.STL"/>
      </geometry>
    </collision>
  </link>
  <joint name="right_arm_eef_G2_joint2" type="prismatic">
    <origin rpy="0 1.5708 0" xyz="0.0736 -0.05 -0.015"/>
    <parent link="right_arm_eef_G2_base_link"/>
    <child link="right_arm_eef_G2_link2"/>
    <axis xyz="0 1 0"/>
    <limit effort="3" lower="0" upper="0.034" velocity="1"/>
    <mimic joint="right_arm_eef_gripper_joint" multiplier="0.034" offset="0"/>
  </joint>
  <joint name="right_arm_eef_gripper_joint" type="revolute">
    <origin rpy="0 0 0" xyz="0 0 0"/>
    <axis xyz="0 0 1"/>
    <parent link="right_arm_eef_G2_base_link"/>
    <child link="right_arm_eef_rotate_motor"/>
    <limit effort="20" lower="0" upper="1" velocity="3.1415926"/>
  </joint>
  <link name="right_arm_eef_rotate_motor"/>
  <joint name="right_arm_gripper_connector" type="fixed">
    <origin rpy="0 0 0" xyz="0.009 0 0"/>
    <parent link="right_arm_flange"/>
    <child link="right_arm_eef_G2_base_link"/>
  </joint>
  <link name="right_arm_end_link">
    <inertial>
      <origin rpy="0 0 0" xyz="-0.104492 0 0"/>
      <mass value="0.605"/>
      <inertia ixx="0.0003483689417" ixy="0.0000002800965" ixz="-0.0000000560724" iyy="0.0070013022796" iyz="0.0000013076668" izz="0.007251995256600001"/>
    </inertial>
  </link>
  <joint name="right_arm_eef_end_joint" type="fixed">
    <origin rpy="0 0 0" xyz="0.1602 0 0"/>
    <parent link="right_arm_flange"/>
    <child link="right_arm_end_link"/>
  </joint>
  <ros2_control name="right_arm_eef_eef_ros2_control" type="actuator">
    <hardware>
      <plugin>airbot_ros2_control/DmActuatorHardware</plugin>
      <param name="can_interface">can_right</param>
      <param name="motor_id">7</param>
      <param name="use_as_actuator">true</param>
      <param name="is_pos_normalized">true</param>
      <param name="upper_limit">-1.6</param>
      <param name="lower_limit">0</param>
    </hardware>
    <joint name="right_arm_eef_gripper_joint">
      <command_interface name="internal/position">
          </command_interface>
      <command_interface name="internal/velocity">
          </command_interface>
      <command_interface name="internal/effort">
          </command_interface>
      <command_interface name="internal/control_mode_command"/>
      <command_interface name="internal/max_velocity_thres"/>
      <command_interface name="internal/max_effort_thres"/>
      <command_interface name="internal/mit_kp"/>
      <command_interface name="internal/mit_kd"/>
      <state_interface name="position">
        <param name="initial_value">0.0</param>
      </state_interface>
      <state_interface name="velocity"/>
      <state_interface name="effort"/>
      <state_interface name="motor_temperature"/>
      <state_interface name="mos_temperature"/>
      <state_interface name="error_id"/>
    </joint>
  </ros2_control>
  <!-- To solve the warning: The root link base_link has an inertia specified in the URDF, but KDL does not support a root link with an inertia.  As a workaround, you can add an extra dummy link to your URDF.  -->
  <link name="world"/>
  <!-- TODO: if joint type is floating, [kdl_parser]: Converting unknown joint type of joint 'fixed_base' into a fixed joint. [moveit_2580797882.moveit.ros.current_state_monitor] Unable to update multi-DOF joint 'fixed_base':Failure to lookup transform between 'world'and 'base_link' with TF exception: "world" passed to lookupTransform argument target_frame does not exist. The complete state of the robot is not yet known.  Missing fixed_base  -->
  <joint name="fixed_base" type="fixed">
    <origin rpy="0 0 0" xyz="0 0 0"/>
    <parent link="world"/>
    <child link="base_link"/>
  </joint>
  <!-- Connect the arms to the slide -->
  <joint name="left_arm_fixed_joint" type="fixed">
    <origin rpy="1.57079633 0 2.356194490192345" xyz="0.10174 0.02283 0.09475"/>
    <parent link="slide_link"/>
    <child link="left_arm_base_link"/>
  </joint>
  <joint name="right_arm_fixed_joint" type="fixed">
    <origin rpy="-1.57079633 0 0.7853981633974483" xyz="-0.10174 0.02283 0.09475"/>
    <parent link="slide_link"/>
    <child link="right_arm_base_link"/>
  </joint>
  <!-- Slide and Head -->
  <link name="slide_link">
    <inertial>
      <origin rpy="0 0 0" xyz="-7.90494393625066E-05 0.067355217450789 0.10519083626064"/>
      <mass value="2.87043102920673"/>
      <inertia ixx="0.00899755064402379" ixy="6.09937870252811E-07" ixz="2.90775161414524E-06" iyy="0.0119634133355932" iyz="-0.000250919444280722" izz="0.00864817587777869"/>
    </inertial>
    <visual>
      <origin rpy="0 0 0" xyz="0 0 0"/>
      <geometry>
        <mesh filename="package://mmk2_urdf/meshes/mmk2/visual/slide_link.STL"/>
      </geometry>
      <material name="">
        <color rgba="0.752941176470588 0.752941176470588 0.752941176470588 1"/>
      </material>
    </visual>
    <collision>
      <origin rpy="0 0 0" xyz="0 0 0"/>
      <geometry>
        <mesh filename="package://mmk2_urdf/meshes/mmk2/collision/slide_link.STL"/>
      </geometry>
    </collision>
  </link>
  <joint name="slide_joint" type="prismatic">
    <origin rpy="3.1416 0 1.5708" xyz="0.033942 -0.00025 1.406"/>
    <parent link="base_link"/>
    <child link="slide_link"/>
    <axis xyz="0 0 1"/>
    <limit effort="5" lower="-0.04" upper="0.87" velocity="0.3"/>
  </joint>
  <link name="head_yaw_link">
    <inertial>
      <origin rpy="0 0 0" xyz="0.0118490941462296 0.000491254783341499 0.0390231494943873"/>
      <mass value="0.263127360420809"/>
      <inertia ixx="0.000185798854547827" ixy="2.64309797822853E-07" ixz="-2.93582511724902E-05" iyy="0.000173833362201622" iyz="-2.8054841555532E-06" izz="9.38655776831082E-05"/>
    </inertial>
    <visual>
      <origin rpy="0 0 0" xyz="0 0 0"/>
      <geometry>
        <mesh filename="package://mmk2_urdf/meshes/mmk2/visual/head_yaw_link.STL"/>
      </geometry>
      <material name="">
        <color rgba="0.752941176470588 0.752941176470588 0.752941176470588 1"/>
      </material>
    </visual>
    <collision>
      <origin rpy="0 0 0" xyz="0 0 0"/>
      <geometry>
        <mesh filename="package://mmk2_urdf/meshes/mmk2/collision/head_yaw_link.STL"/>
      </geometry>
    </collision>
  </link>
  <joint name="head_yaw_joint" type="revolute">
    <origin rpy="3.1416 0 0" xyz="0 0.1735 0.07242"/>
    <parent link="slide_link"/>
    <child link="head_yaw_link"/>
    <axis xyz="0 0 1"/>
    <limit effort="0" lower="-0.5" upper="0.5" velocity="0"/>
  </joint>
  <link name="head_pitch_link">
    <inertial>
      <origin rpy="0 0 0" xyz="0.0244659096221799 -0.108421751901101 -0.00311687659834824"/>
      <mass value="0.500765947013434"/>
      <inertia ixx="0.00157924187002826" ixy="2.16781765858799E-05" ixz="-1.02638171835218E-06" iyy="0.000804096450222595" iyz="1.48815549401623E-05" izz="0.00113048749298996"/>
    </inertial>
    <visual>
      <origin rpy="3.1415 0 0" xyz="0 0 0"/>
      <geometry>
        <mesh filename="package://mmk2_urdf/meshes/mmk2/visual/head_pitch_link.STL"/>
      </geometry>
      <material name="">
        <color rgba="0.752941176470588 0.752941176470588 0.752941176470588 1"/>
      </material>
    </visual>
    <collision>
      <origin rpy="3.1415 0 0" xyz="0 0 0"/>
      <geometry>
        <mesh filename="package://mmk2_urdf/meshes/mmk2/collision/head_pitch_link.STL"/>
      </geometry>
    </collision>
  </link>
  <joint name="head_pitch_joint" type="revolute">
    <origin rpy="1.5708 0.0 -1.5708" xyz="0.00099952 3.1059E-05 0.058"/>
    <parent link="head_yaw_link"/>
    <child link="head_pitch_link"/>
    <axis xyz="0 0 1"/>
    <limit effort="0" lower="-1.1" upper="0.3" velocity="0"/>
  </joint>
  <joint name="camera_fixed_joint" type="fixed">
    <origin rpy="3.1416 -1.5708 -0.33" xyz="0.0755 0.1855 -0.035"/>
    <parent link="head_pitch_link"/>
    <child link="head_camera_link"/>
  </joint>
  <link name="head_camera_link"/>
</robot>
